Traceback (most recent call last):
  File "/cvmfs/soft.computecanada.ca/easybuild/software/2023/x86-64-v4/Compiler/gcccore/python/3.10.13/lib/python3.10/urllib/request.py", line 1348, in do_open
    h.request(req.get_method(), req.selector, req.data, headers,
  File "/cvmfs/soft.computecanada.ca/easybuild/software/2023/x86-64-v4/Compiler/gcccore/python/3.10.13/lib/python3.10/http/client.py", line 1283, in request
    self._send_request(method, url, body, headers, encode_chunked)
  File "/cvmfs/soft.computecanada.ca/easybuild/software/2023/x86-64-v4/Compiler/gcccore/python/3.10.13/lib/python3.10/http/client.py", line 1329, in _send_request
    self.endheaders(body, encode_chunked=encode_chunked)
  File "/cvmfs/soft.computecanada.ca/easybuild/software/2023/x86-64-v4/Compiler/gcccore/python/3.10.13/lib/python3.10/http/client.py", line 1278, in endheaders
    self._send_output(message_body, encode_chunked=encode_chunked)
  File "/cvmfs/soft.computecanada.ca/easybuild/software/2023/x86-64-v4/Compiler/gcccore/python/3.10.13/lib/python3.10/http/client.py", line 1038, in _send_output
    self.send(msg)
  File "/cvmfs/soft.computecanada.ca/easybuild/software/2023/x86-64-v4/Compiler/gcccore/python/3.10.13/lib/python3.10/http/client.py", line 976, in send
    self.connect()
  File "/cvmfs/soft.computecanada.ca/easybuild/software/2023/x86-64-v4/Compiler/gcccore/python/3.10.13/lib/python3.10/http/client.py", line 1448, in connect
    super().connect()
  File "/cvmfs/soft.computecanada.ca/easybuild/software/2023/x86-64-v4/Compiler/gcccore/python/3.10.13/lib/python3.10/http/client.py", line 942, in connect
    self.sock = self._create_connection(
  File "/cvmfs/soft.computecanada.ca/easybuild/software/2023/x86-64-v4/Compiler/gcccore/python/3.10.13/lib/python3.10/socket.py", line 845, in create_connection
    raise err
  File "/cvmfs/soft.computecanada.ca/easybuild/software/2023/x86-64-v4/Compiler/gcccore/python/3.10.13/lib/python3.10/socket.py", line 833, in create_connection
    sock.connect(sa)
OSError: [Errno 101] Network is unreachable

During handling of the above exception, another exception occurred:

Traceback (most recent call last):
  File "/home/pedro36/links/projects/def-leszek/pedro36/workspace/CLIP-LoRA-Original/main.py", line 53, in <module>
    main()
  File "/home/pedro36/links/projects/def-leszek/pedro36/workspace/CLIP-LoRA-Original/main.py", line 20, in main
    clip_model, preprocess = clip.load(args.backbone)
  File "/lustre09/project/6036820/pedro36/workspace/CLIP-LoRA-Original/clip/clip.py", line 117, in load
    model_path = _download(_MODELS[name], download_root or os.path.expanduser("~/.cache/clip"))
  File "/lustre09/project/6036820/pedro36/workspace/CLIP-LoRA-Original/clip/clip.py", line 56, in _download
    with urllib.request.urlopen(url) as source, open(download_target, "wb") as output:
  File "/cvmfs/soft.computecanada.ca/easybuild/software/2023/x86-64-v4/Compiler/gcccore/python/3.10.13/lib/python3.10/urllib/request.py", line 216, in urlopen
    return opener.open(url, data, timeout)
  File "/cvmfs/soft.computecanada.ca/easybuild/software/2023/x86-64-v4/Compiler/gcccore/python/3.10.13/lib/python3.10/urllib/request.py", line 519, in open
    response = self._open(req, data)
  File "/cvmfs/soft.computecanada.ca/easybuild/software/2023/x86-64-v4/Compiler/gcccore/python/3.10.13/lib/python3.10/urllib/request.py", line 536, in _open
    result = self._call_chain(self.handle_open, protocol, protocol +
  File "/cvmfs/soft.computecanada.ca/easybuild/software/2023/x86-64-v4/Compiler/gcccore/python/3.10.13/lib/python3.10/urllib/request.py", line 496, in _call_chain
    result = func(*args)
  File "/cvmfs/soft.computecanada.ca/easybuild/software/2023/x86-64-v4/Compiler/gcccore/python/3.10.13/lib/python3.10/urllib/request.py", line 1391, in https_open
    return self.do_open(http.client.HTTPSConnection, req,
  File "/cvmfs/soft.computecanada.ca/easybuild/software/2023/x86-64-v4/Compiler/gcccore/python/3.10.13/lib/python3.10/urllib/request.py", line 1351, in do_open
    raise URLError(err)
urllib.error.URLError: <urlopen error [Errno 101] Network is unreachable>
